<?xml version="1.0"?>
<sdf version="1.6">
  <model name="tadeocar_v1">
    <static>false</static>

    <!-- Base Link (Chasis Principal) -->
    <link name="base_link">
      <pose>0 0 0.1 0 0 0</pose>

      <inertial>
        <mass>50.0</mass>
        <inertia>
          <ixx>3.042</ixx>
          <iyy>6.375</iyy>
          <izz>8.667</izz>
          <ixy>0</ixy>
          <ixz>0</ixz>
          <iyz>0</iyz>
        </inertia>
      </inertial>

      <collision name="base_collision">
        <pose>0 0 0.155 0 0 0</pose>
        <geometry>
          <mesh>
            <uri>model://tadeocar_v1/meshes/chassis/chasis_base.dae</uri>
            <scale>1 1 1</scale>
          </mesh>
        </geometry>
      </collision>

      <visual name="base_visual">
        <pose>0 0 0.155 0 0 0</pose>
        <geometry>
          <mesh>
            <uri>model://tadeocar_v1/meshes/chassis/chasis_base.dae</uri>
            <scale>1 1 1</scale>
          </mesh>
        </geometry>
        <material>
          <ambient>0.2 0.2 0.8 1</ambient>
          <diffuse>0.2 0.2 0.8 1</diffuse>
        </material>
      </visual>
    </link>

    <!-- Chasis Superior -->
    <link name="chasis_link">
      <pose>0 0 0.45 0 0 0</pose>

      <inertial>
        <mass>10.0</mass>
        <pose>0 0 -0.05 0 0 0</pose>
        <inertia>
          <ixx>0.433</ixx>
          <iyy>0.667</iyy>
          <izz>0.833</izz>
          <ixy>0</ixy>
          <ixz>0</ixz>
          <iyz>0</iyz>
        </inertia>
      </inertial>

      <collision name="chasis_collision">
        <pose>-0.49 0.39 -0.126 1.5708 0 3.14159</pose>
        <geometry>
          <mesh>
            <uri>model://tadeocar_v1/meshes/chassis/chasis.dae</uri>
            <scale>0.001 0.001 0.001</scale>
          </mesh>
        </geometry>
      </collision>

      <visual name="chasis_visual">
        <pose>-0.49 0.39 -0.126 1.5708 0 3.14159</pose>
        <geometry>
          <mesh>
            <uri>model://tadeocar_v1/meshes/chassis/chasis.dae</uri>
            <scale>0.001 0.001 0.001</scale>
          </mesh>
        </geometry>
        <material>
          <ambient>0.8 0.2 0.2 1</ambient>
          <diffuse>0.8 0.2 0.2 1</diffuse>
        </material>
      </visual>
    </link>

    <joint name="chasis_joint" type="fixed">
      <parent>base_link</parent>
      <child>chasis_link</child>
    </joint>

    <!-- Front Left Steering -->
    <link name="front_left_steering_link">
      <pose>0.478 0.275 0.1 0 0 0</pose>

      <inertial>
        <mass>6.0</mass>
        <inertia>
          <ixx>0.05</ixx>
          <iyy>0.05</iyy>
          <izz>0.05</izz>
          <ixy>0</ixy>
          <ixz>0</ixz>
          <iyz>0</iyz>
        </inertia>
      </inertial>

      <collision name="front_left_steering_collision">
        <pose>0 0 0.227 0 3.14159 3.14159</pose>
        <geometry>
          <mesh>
            <uri>model://tadeocar_v1/meshes/suspension/suspension.dae</uri>
            <scale>1 1 1</scale>
          </mesh>
        </geometry>
      </collision>

      <visual name="front_left_steering_visual">
        <pose>0 0 0.227 0 3.14159 3.14159</pose>
        <geometry>
          <mesh>
            <uri>model://tadeocar_v1/meshes/suspension/suspension.dae</uri>
            <scale>1 1 1</scale>
          </mesh>
        </geometry>
        <material>
          <ambient>0.5 0.5 0.5 1</ambient>
          <diffuse>0.5 0.5 0.5 1</diffuse>
        </material>
      </visual>
    </link>

    <joint name="front_left_steering_joint" type="revolute">
      <parent>base_link</parent>
      <child>front_left_steering_link</child>
      <axis>
        <xyz>0 0 1</xyz>
        <limit>
          <lower>-2.356</lower>
          <upper>2.356</upper>
          <effort>100</effort>
          <velocity>1.0</velocity>
        </limit>
        <dynamics>
          <damping>5.0</damping>
          <friction>2.0</friction>
        </dynamics>
      </axis>
    </joint>

    <!-- Front Left Wheel -->
    <link name="front_left_wheel_link">
      <pose>0.528 0.275 0.1 0 0 0</pose>

      <inertial>
        <mass>6.0</mass>
        <inertia>
          <ixx>0.0364</ixx>
          <iyy>0.06</iyy>
          <izz>0.0364</izz>
          <ixy>0</ixy>
          <ixz>0</ixz>
          <iyz>0</iyz>
        </inertia>
      </inertial>

      <collision name="front_left_wheel_collision">
        <pose>0 0 0 1.5708 0 0</pose>
        <geometry>
          <mesh>
            <uri>model://tadeocar_v1/meshes/wheels/wheel.dae</uri>
            <scale>1 1 1</scale>
          </mesh>
        </geometry>
        <surface>
          <friction>
            <ode>
              <mu>2.5</mu>
              <mu2>2.5</mu2>
              <slip1>0.0</slip1>
              <slip2>0.0</slip2>
            </ode>
          </friction>
          <contact>
            <ode>
              <kp>1000000.0</kp>
              <kd>100.0</kd>
              <min_depth>0.001</min_depth>
            </ode>
          </contact>
        </surface>
      </collision>

      <visual name="front_left_wheel_visual">
        <pose>0 0 0 1.5708 0 0</pose>
        <geometry>
          <mesh>
            <uri>model://tadeocar_v1/meshes/wheels/wheel.dae</uri>
            <scale>1 1 1</scale>
          </mesh>
        </geometry>
        <material>
          <ambient>0.2 0.2 0.2 1</ambient>
          <diffuse>0.2 0.2 0.2 1</diffuse>
        </material>
      </visual>
    </link>

    <joint name="front_left_wheel_joint" type="revolute">
      <parent>front_left_steering_link</parent>
      <child>front_left_wheel_link</child>
      <axis>
        <xyz>0 1 0</xyz>
        <limit>
          <effort>200.0</effort>
          <velocity>100</velocity>
        </limit>
        <dynamics>
          <damping>0.01</damping>
          <friction>0.01</friction>
        </dynamics>
      </axis>
    </joint>

    <!-- Front Right Steering -->
    <link name="front_right_steering_link">
      <pose>0.478 -0.275 0.1 0 0 0</pose>

      <inertial>
        <mass>6.0</mass>
        <inertia>
          <ixx>0.05</ixx>
          <iyy>0.05</iyy>
          <izz>0.05</izz>
          <ixy>0</ixy>
          <ixz>0</ixz>
          <iyz>0</iyz>
        </inertia>
      </inertial>

      <collision name="front_right_steering_collision">
        <pose>0 0 0.227 0 3.14159 -3.14159</pose>
        <geometry>
          <mesh>
            <uri>model://tadeocar_v1/meshes/suspension/suspension.dae</uri>
            <scale>1 1 1</scale>
          </mesh>
        </geometry>
      </collision>

      <visual name="front_right_steering_visual">
        <pose>0 0 0.227 0 3.14159 -3.14159</pose>
        <geometry>
          <mesh>
            <uri>model://tadeocar_v1/meshes/suspension/suspension.dae</uri>
            <scale>1 1 1</scale>
          </mesh>
        </geometry>
        <material>
          <ambient>0.5 0.5 0.5 1</ambient>
          <diffuse>0.5 0.5 0.5 1</diffuse>
        </material>
      </visual>
    </link>

    <joint name="front_right_steering_joint" type="revolute">
      <parent>base_link</parent>
      <child>front_right_steering_link</child>
      <axis>
        <xyz>0 0 1</xyz>
        <limit>
          <lower>-2.356</lower>
          <upper>2.356</upper>
          <effort>100</effort>
          <velocity>1.0</velocity>
        </limit>
        <dynamics>
          <damping>5.0</damping>
          <friction>2.0</friction>
        </dynamics>
      </axis>
    </joint>

    <!-- Front Right Wheel -->
    <link name="front_right_wheel_link">
      <pose>0.528 -0.275 0.1 0 0 0</pose>

      <inertial>
        <mass>6.0</mass>
        <inertia>
          <ixx>0.0364</ixx>
          <iyy>0.06</iyy>
          <izz>0.0364</izz>
          <ixy>0</ixy>
          <ixz>0</ixz>
          <iyz>0</iyz>
        </inertia>
      </inertial>

      <collision name="front_right_wheel_collision">
        <pose>0 0 0 1.5708 0 0</pose>
        <geometry>
          <mesh>
            <uri>model://tadeocar_v1/meshes/wheels/wheel.dae</uri>
            <scale>1 1 1</scale>
          </mesh>
        </geometry>
        <surface>
          <friction>
            <ode>
              <mu>2.5</mu>
              <mu2>2.5</mu2>
              <slip1>0.0</slip1>
              <slip2>0.0</slip2>
            </ode>
          </friction>
          <contact>
            <ode>
              <kp>1000000.0</kp>
              <kd>100.0</kd>
              <min_depth>0.001</min_depth>
            </ode>
          </contact>
        </surface>
      </collision>

      <visual name="front_right_wheel_visual">
        <pose>0 0 0 1.5708 0 0</pose>
        <geometry>
          <mesh>
            <uri>model://tadeocar_v1/meshes/wheels/wheel.dae</uri>
            <scale>1 1 1</scale>
          </mesh>
        </geometry>
        <material>
          <ambient>0.2 0.2 0.2 1</ambient>
          <diffuse>0.2 0.2 0.2 1</diffuse>
        </material>
      </visual>
    </link>

    <joint name="front_right_wheel_joint" type="revolute">
      <parent>front_right_steering_link</parent>
      <child>front_right_wheel_link</child>
      <axis>
        <xyz>0 1 0</xyz>
        <limit>
          <effort>200.0</effort>
          <velocity>100</velocity>
        </limit>
        <dynamics>
          <damping>0.01</damping>
          <friction>0.01</friction>
        </dynamics>
      </axis>
    </joint>

    <!-- Rear Left Steering -->
    <link name="rear_left_steering_link">
      <pose>-0.58 0.275 0.1 0 0 0</pose>

      <inertial>
        <mass>6.0</mass>
        <inertia>
          <ixx>0.05</ixx>
          <iyy>0.05</iyy>
          <izz>0.05</izz>
          <ixy>0</ixy>
          <ixz>0</ixz>
          <iyz>0</iyz>
        </inertia>
      </inertial>

      <collision name="rear_left_steering_collision">
        <pose>0 0 0.227 0 3.14159 0</pose>
        <geometry>
          <mesh>
            <uri>model://tadeocar_v1/meshes/suspension/suspension.dae</uri>
            <scale>1 1 1</scale>
          </mesh>
        </geometry>
      </collision>

      <visual name="rear_left_steering_visual">
        <pose>0 0 0.227 0 3.14159 0</pose>
        <geometry>
          <mesh>
            <uri>model://tadeocar_v1/meshes/suspension/suspension.dae</uri>
            <scale>1 1 1</scale>
          </mesh>
        </geometry>
        <material>
          <ambient>0.5 0.5 0.5 1</ambient>
          <diffuse>0.5 0.5 0.5 1</diffuse>
        </material>
      </visual>
    </link>

    <joint name="rear_left_steering_joint" type="revolute">
      <parent>base_link</parent>
      <child>rear_left_steering_link</child>
      <axis>
        <xyz>0 0 1</xyz>
        <limit>
          <lower>-2.356</lower>
          <upper>2.356</upper>
          <effort>100</effort>
          <velocity>1.0</velocity>
        </limit>
        <dynamics>
          <damping>5.0</damping>
          <friction>2.0</friction>
        </dynamics>
      </axis>
    </joint>

    <!-- Rear Left Wheel -->
    <link name="rear_left_wheel_link">
      <pose>-0.63 0.275 0.1 0 0 0</pose>

      <inertial>
        <mass>6.0</mass>
        <inertia>
          <ixx>0.0364</ixx>
          <iyy>0.06</iyy>
          <izz>0.0364</izz>
          <ixy>0</ixy>
          <ixz>0</ixz>
          <iyz>0</iyz>
        </inertia>
      </inertial>

      <collision name="rear_left_wheel_collision">
        <pose>0 0 0 1.5708 0 0</pose>
        <geometry>
          <mesh>
            <uri>model://tadeocar_v1/meshes/wheels/wheel.dae</uri>
            <scale>1 1 1</scale>
          </mesh>
        </geometry>
        <surface>
          <friction>
            <ode>
              <mu>2.5</mu>
              <mu2>2.5</mu2>
              <slip1>0.0</slip1>
              <slip2>0.0</slip2>
            </ode>
          </friction>
          <contact>
            <ode>
              <kp>1000000.0</kp>
              <kd>100.0</kd>
              <min_depth>0.001</min_depth>
            </ode>
          </contact>
        </surface>
      </collision>

      <visual name="rear_left_wheel_visual">
        <pose>0 0 0 1.5708 0 0</pose>
        <geometry>
          <mesh>
            <uri>model://tadeocar_v1/meshes/wheels/wheel.dae</uri>
            <scale>1 1 1</scale>
          </mesh>
        </geometry>
        <material>
          <ambient>0.2 0.2 0.2 1</ambient>
          <diffuse>0.2 0.2 0.2 1</diffuse>
        </material>
      </visual>
    </link>

    <joint name="rear_left_wheel_joint" type="revolute">
      <parent>rear_left_steering_link</parent>
      <child>rear_left_wheel_link</child>
      <axis>
        <xyz>0 1 0</xyz>
        <limit>
          <effort>200.0</effort>
          <velocity>100</velocity>
        </limit>
        <dynamics>
          <damping>0.01</damping>
          <friction>0.01</friction>
        </dynamics>
      </axis>
    </joint>

    <!-- Rear Right Steering -->
    <link name="rear_right_steering_link">
      <pose>-0.58 -0.275 0.1 0 0 0</pose>

      <inertial>
        <mass>6.0</mass>
        <inertia>
          <ixx>0.05</ixx>
          <iyy>0.05</iyy>
          <izz>0.05</izz>
          <ixy>0</ixy>
          <ixz>0</ixz>
          <iyz>0</iyz>
        </inertia>
      </inertial>

      <collision name="rear_right_steering_collision">
        <pose>0 0 0.227 0 3.14159 0</pose>
        <geometry>
          <mesh>
            <uri>model://tadeocar_v1/meshes/suspension/suspension.dae</uri>
            <scale>1 1 1</scale>
          </mesh>
        </geometry>
      </collision>

      <visual name="rear_right_steering_visual">
        <pose>0 0 0.227 0 3.14159 0</pose>
        <geometry>
          <mesh>
            <uri>model://tadeocar_v1/meshes/suspension/suspension.dae</uri>
            <scale>1 1 1</scale>
          </mesh>
        </geometry>
        <material>
          <ambient>0.5 0.5 0.5 1</ambient>
          <diffuse>0.5 0.5 0.5 1</diffuse>
        </material>
      </visual>
    </link>

    <joint name="rear_right_steering_joint" type="revolute">
      <parent>base_link</parent>
      <child>rear_right_steering_link</child>
      <axis>
        <xyz>0 0 1</xyz>
        <limit>
          <lower>-2.356</lower>
          <upper>2.356</upper>
          <effort>100</effort>
          <velocity>1.0</velocity>
        </limit>
        <dynamics>
          <damping>5.0</damping>
          <friction>2.0</friction>
        </dynamics>
      </axis>
    </joint>

    <!-- Rear Right Wheel -->
    <link name="rear_right_wheel_link">
      <pose>-0.63 -0.275 0.1 0 0 0</pose>

      <inertial>
        <mass>6.0</mass>
        <inertia>
          <ixx>0.0364</ixx>
          <iyy>0.06</iyy>
          <izz>0.0364</izz>
          <ixy>0</ixy>
          <ixz>0</ixz>
          <iyz>0</iyz>
        </inertia>
      </inertial>

      <collision name="rear_right_wheel_collision">
        <pose>0 0 0 1.5708 0 0</pose>
        <geometry>
          <mesh>
            <uri>model://tadeocar_v1/meshes/wheels/wheel.dae</uri>
            <scale>1 1 1</scale>
          </mesh>
        </geometry>
        <surface>
          <friction>
            <ode>
              <mu>2.5</mu>
              <mu2>2.5</mu2>
              <slip1>0.0</slip1>
              <slip2>0.0</slip2>
            </ode>
          </friction>
          <contact>
            <ode>
              <kp>1000000.0</kp>
              <kd>100.0</kd>
              <min_depth>0.001</min_depth>
            </ode>
          </contact>
        </surface>
      </collision>

      <visual name="rear_right_wheel_visual">
        <pose>0 0 0 1.5708 0 0</pose>
        <geometry>
          <mesh>
            <uri>model://tadeocar_v1/meshes/wheels/wheel.dae</uri>
            <scale>1 1 1</scale>
          </mesh>
        </geometry>
        <material>
          <ambient>0.2 0.2 0.2 1</ambient>
          <diffuse>0.2 0.2 0.2 1</diffuse>
        </material>
      </visual>
    </link>

    <joint name="rear_right_wheel_joint" type="revolute">
      <parent>rear_right_steering_link</parent>
      <child>rear_right_wheel_link</child>
      <axis>
        <xyz>0 1 0</xyz>
        <limit>
          <effort>200.0</effort>
          <velocity>100</velocity>
        </limit>
        <dynamics>
          <damping>0.01</damping>
          <friction>0.01</friction>
        </dynamics>
      </axis>
    </joint>

    <!-- LiDAR Sensor (Axioma compatible) -->
    <link name="base_scan">
      <pose>0.55 0 0.43 0 0 0</pose>

      <inertial>
        <mass>0.125</mass>
        <inertia>
          <ixx>0.001</ixx>
          <iyy>0.001</iyy>
          <izz>0.001</izz>
          <ixy>0</ixy>
          <ixz>0</ixz>
          <iyz>0</iyz>
        </inertia>
      </inertial>

      <collision name="lidar_sensor_collision">
        <geometry>
          <cylinder>
            <radius>0.035</radius>
            <length>0.030</length>
          </cylinder>
        </geometry>
      </collision>base_scan

      <visual name="lidar_sensor_visual">
        <geometry>
          <cylinder>
            <radius>0.035</radius>
            <length>0.030</length>
          </cylinder>
        </geometry>
        <material>
          <ambient>0.1 0.1 0.1 1</ambient>
          <diffuse>0.1 0.1 0.1 1</diffuse>
        </material>
      </visual>

      <sensor name="hls_lfcd_lds" type="ray">
        <pose>0 0 0 0 0 0</pose>
        <always_on>true</always_on>
        <visualize>true</visualize>
        <update_rate>20</update_rate>
        <ray>
          <scan>
            <horizontal>
		    <samples>320</samples>
		    <resolution>1</resolution>
		    <min_angle>-2.79253</min_angle>   <!-- -160° -->
    		    <max_angle> 2.79253</max_angle>   <!-- +160° -->
	  </horizontal>
          </scan>
          <range>
            <min>0.36</min>
            <max>3.5</max>
            <resolution>0.02000</resolution>
          </range>
          <!--noise>
            <type>gaussian</type>
            <mean>0.0</mean>
            <stddev>0.01</stddev>
          </noise-->
        </ray>
        <plugin name="laserscan" filename="libgazebo_ros_ray_sensor.so">
          <ros>
            <remapping>~/out:=scan</remapping>
          </ros>
          <qos>
            <topic name="scan">
              <publisher>
                <reliability>best_effort</reliability>
              </publisher>
            </topic>
          </qos>
          <output_type>sensor_msgs/LaserScan</output_type>
          <frame_name>base_scan</frame_name>
        </plugin>
      </sensor>
    </link>

    <joint name="lidar_joint" type="fixed">
      <parent>base_link</parent>
      <child>base_scan</child>
    </joint>

    <!-- Stereo Camera Base Link -->
    <link name="stereo_camera_base">
      <pose>0.55 0 0.50 0 0 0</pose>

      <inertial>
        <mass>0.5</mass>
        <inertia>
          <ixx>0.001</ixx>
          <iyy>0.001</iyy>
          <izz>0.001</izz>
          <ixy>0</ixy>
          <ixz>0</ixz>
          <iyz>0</iyz>
        </inertia>
      </inertial>

      <!-- Collision removed - cameras are sensors only -->

      <visual name="stereo_camera_base_visual">
        <pose>0 0 0 0 0 1.5708</pose>
        <geometry>
          <box>
            <size>0.15 0.05 0.03</size>
          </box>
        </geometry>
        <material>
          <ambient>0.2 0.2 0.2 1</ambient>
          <diffuse>0.2 0.2 0.2 1</diffuse>
        </material>
      </visual>
    </link>

    <joint name="stereo_camera_base_joint" type="fixed">
      <parent>base_link</parent>
      <child>stereo_camera_base</child>
    </joint>

    <!-- Left Camera Link -->
    <link name="camera_left">
      <pose>0.58 0.06 0.50 0 0 0</pose>

      <inertial>
        <mass>0.2</mass>
        <inertia>
          <ixx>0.0001</ixx>
          <iyy>0.0001</iyy>
          <izz>0.0001</izz>
          <ixy>0</ixy>
          <ixz>0</ixz>
          <iyz>0</iyz>
        </inertia>
      </inertial>

      <!-- Collision removed - cameras are sensors only -->

      <visual name="camera_left_visual">
        <pose>0 0 0 0 1.5708 0</pose>
        <geometry>
          <cylinder>
            <radius>0.01</radius>
            <length>0.01</length>
          </cylinder>
        </geometry>
        <material>
          <ambient>0.1 0.1 0.1 1</ambient>
          <diffuse>0.1 0.1 0.1 1</diffuse>
        </material>
      </visual>

      <sensor name="camera_left_sensor" type="camera">
        <pose>0.005 0 0 0 0 0</pose>
        <always_on>true</always_on>
        <update_rate>30</update_rate>
        <visualize>true</visualize>
        <camera name="camera_left">
          <horizontal_fov>1.3962634</horizontal_fov>
          <image>
            <width>1280</width>
            <height>720</height>
            <format>R8G8B8</format>
          </image>
          <clip>
            <near>0.02</near>
            <far>300</far>
          </clip>
          <noise>
            <type>gaussian</type>
            <mean>0.0</mean>
            <stddev>0.007</stddev>
          </noise>
        </camera>
        <plugin name="camera_left_controller" filename="libgazebo_ros_camera.so">
          <ros>
            <namespace>/</namespace>
            <remapping>~/image_raw:=camera/left/image_raw</remapping>
            <remapping>~/camera_info:=camera/left/camera_info</remapping>
          </ros>
          <camera_name>camera_left</camera_name>
          <frame_name>camera_left_optical</frame_name>
          <hack_baseline>0.12</hack_baseline>
        </plugin>
      </sensor>
    </link>

    <joint name="camera_left_joint" type="fixed">
      <parent>stereo_camera_base</parent>
      <child>camera_left</child>
    </joint>

    <!-- Right Camera Link -->
    <link name="camera_right">
      <pose>0.58 -0.06 0.50 0 0 0</pose>

      <inertial>
        <mass>0.2</mass>
        <inertia>
          <ixx>0.0001</ixx>
          <iyy>0.0001</iyy>
          <izz>0.0001</izz>
          <ixy>0</ixy>
          <ixz>0</ixz>
          <iyz>0</iyz>
        </inertia>
      </inertial>

      <!-- Collision removed - cameras are sensors only -->

      <visual name="camera_right_visual">
        <pose>0 0 0 0 1.5708 0</pose>
        <geometry>
          <cylinder>
            <radius>0.01</radius>
            <length>0.01</length>
          </cylinder>
        </geometry>
        <material>
          <ambient>0.1 0.1 0.1 1</ambient>
          <diffuse>0.1 0.1 0.1 1</diffuse>
        </material>
      </visual>

      <sensor name="camera_right_sensor" type="camera">
        <pose>0.005 0 0 0 0 0</pose>
        <always_on>true</always_on>
        <update_rate>30</update_rate>
        <visualize>true</visualize>
        <camera name="camera_right">
          <horizontal_fov>1.3962634</horizontal_fov>
          <image>
            <width>1280</width>
            <height>720</height>
            <format>R8G8B8</format>
          </image>
          <clip>
            <near>0.02</near>
            <far>300</far>
          </clip>
          <noise>
            <type>gaussian</type>
            <mean>0.0</mean>
            <stddev>0.007</stddev>
          </noise>
        </camera>
        <plugin name="camera_right_controller" filename="libgazebo_ros_camera.so">
          <ros>
            <namespace>/</namespace>
            <remapping>~/image_raw:=camera/right/image_raw</remapping>
            <remapping>~/camera_info:=camera/right/camera_info</remapping>
          </ros>
          <camera_name>camera_right</camera_name>
          <frame_name>camera_right_optical</frame_name>
          <hack_baseline>0.12</hack_baseline>
        </plugin>
      </sensor>
    </link>

    <joint name="camera_right_joint" type="fixed">
      <parent>stereo_camera_base</parent>
      <child>camera_right</child>
    </joint>

    <!-- Camera Optical Frames -->
    <link name="camera_left_optical">
      <pose>0.585 0.06 0.50 -1.5708 0 -1.5708</pose>
    </link>

    <joint name="camera_left_optical_joint" type="fixed">
      <parent>camera_left</parent>
      <child>camera_left_optical</child>
    </joint>

    <link name="camera_right_optical">
      <pose>0.585 -0.06 0.50 -1.5708 0 -1.5708</pose>
    </link>

    <joint name="camera_right_optical_joint" type="fixed">
      <parent>camera_right</parent>
      <child>camera_right_optical</child>
    </joint>

    <!-- Note: This SDF is for reference only. The simulation uses
         src/tadeocar_gazebo/models/tadeocar_v1/model.sdf with Gz Sim plugins.
         Steering joints use JointPositionController (position control).
         Wheel joints use JointController (velocity control).
         Odometry is published by OdometryPublisher plugin. -->

  </model>
</sdf>
