<sdf version='1.7'>
  <model name='tadeocar_v1'>
    <static>0</static>
    <link name='base_link'>
      <pose>0 0 0.1 0 -0 0</pose>
      <inertial>
        <mass>50</mass>
        <inertia>
          <ixx>4</ixx>
          <iyy>4</iyy>
          <izz>2</izz>
          <ixy>0</ixy>
          <ixz>0</ixz>
          <iyz>0</iyz>
        </inertia>
      </inertial>
      <collision name='base_collision'>
        <pose>0 0 0.155 0 -0 0</pose>
        <geometry>
          <mesh>
            <uri>model://tadeocar_v1/meshes/chassis/chasis_base.dae</uri>
            <scale>1 1 1</scale>
          </mesh>
        </geometry>
      </collision>
      <visual name='base_visual'>
        <pose>0 0 0.155 0 -0 0</pose>
        <geometry>
          <mesh>
            <uri>model://tadeocar_v1/meshes/chassis/chasis_base.dae</uri>
            <scale>1 1 1</scale>
          </mesh>
        </geometry>
        <material>
          <ambient>0.2 0.2 0.8 1</ambient>
          <diffuse>0.2 0.2 0.8 1</diffuse>
        </material>
      </visual>
    </link>
    <link name='chasis_link'>
      <pose>0 0 0.45 0 -0 0</pose>
      <inertial>
        <mass>20</mass>
        <inertia>
          <ixx>1</ixx>
          <iyy>1</iyy>
          <izz>0.5</izz>
          <ixy>0</ixy>
          <ixz>0</ixz>
          <iyz>0</iyz>
        </inertia>
      </inertial>
      <collision name='chasis_collision'>
        <pose>-0.49 0.39 -0.126 1.5708 -0 3.14159</pose>
        <geometry>
          <mesh>
            <uri>model://tadeocar_v1/meshes/chassis/chasis.dae</uri>
            <scale>0.001 0.001 0.001</scale>
          </mesh>
        </geometry>
      </collision>
      <visual name='chasis_visual'>
        <pose>-0.49 0.39 -0.126 1.5708 -0 3.14159</pose>
        <geometry>
          <mesh>
            <uri>model://tadeocar_v1/meshes/chassis/chasis.dae</uri>
            <scale>0.001 0.001 0.001</scale>
          </mesh>
        </geometry>
        <material>
          <ambient>0.8 0.2 0.2 1</ambient>
          <diffuse>0.8 0.2 0.2 1</diffuse>
        </material>
      </visual>
    </link>
    <joint name='chasis_joint' type='fixed'>
      <parent>base_link</parent>
      <child>chasis_link</child>
    </joint>
    <link name='front_left_steering_link'>
      <pose>0.478 0.275 0.1 0 -0 0</pose>
      <inertial>
        <mass>2</mass>
        <inertia>
          <ixx>0.01</ixx>
          <iyy>0.01</iyy>
          <izz>0.01</izz>
          <ixy>0</ixy>
          <ixz>0</ixz>
          <iyz>0</iyz>
        </inertia>
      </inertial>
      <collision name='front_left_steering_collision'>
        <pose>0 0 0.227 3.14159 3e-06 -3e-06</pose>
        <geometry>
          <mesh>
            <uri>model://tadeocar_v1/meshes/suspension/suspension.dae</uri>
            <scale>1 1 1</scale>
          </mesh>
        </geometry>
      </collision>
      <visual name='front_left_steering_visual'>
        <pose>0 0 0.227 3.14159 3e-06 -3e-06</pose>
        <geometry>
          <mesh>
            <uri>model://tadeocar_v1/meshes/suspension/suspension.dae</uri>
            <scale>1 1 1</scale>
          </mesh>
        </geometry>
        <material>
          <ambient>0.5 0.5 0.5 1</ambient>
          <diffuse>0.5 0.5 0.5 1</diffuse>
        </material>
      </visual>
    </link>
    <joint name='front_left_steering_joint' type='revolute'>
      <parent>base_link</parent>
      <child>front_left_steering_link</child>
      <axis>
        <xyz>0 0 1</xyz>
        <limit>
          <lower>-0.5</lower>
          <upper>0.5</upper>
          <effort>100</effort>
          <velocity>1</velocity>
        </limit>
        <dynamics>
          <damping>1</damping>
          <friction>1</friction>
          <spring_reference>0</spring_reference>
          <spring_stiffness>0</spring_stiffness>
        </dynamics>
      </axis>
    </joint>
    <link name='front_left_wheel_link'>
      <pose>0.528 0.275 0.1 0 -0 0</pose>
      <inertial>
        <mass>3</mass>
        <inertia>
          <ixx>0.1</ixx>
          <iyy>0.1</iyy>
          <izz>0.1</izz>
          <ixy>0</ixy>
          <ixz>0</ixz>
          <iyz>0</iyz>
        </inertia>
      </inertial>
      <collision name='front_left_wheel_collision'>
        <pose>0 0 0 1.5708 -0 0</pose>
        <geometry>
          <mesh>
            <uri>model://tadeocar_v1/meshes/wheels/wheel.dae</uri>
            <scale>1 1 1</scale>
          </mesh>
        </geometry>
        <surface>
          <friction>
            <ode>
              <mu>1</mu>
              <mu2>1</mu2>
            </ode>
          </friction>
        </surface>
      </collision>
      <visual name='front_left_wheel_visual'>
        <pose>0 0 0 1.5708 -0 0</pose>
        <geometry>
          <mesh>
            <uri>model://tadeocar_v1/meshes/wheels/wheel.dae</uri>
            <scale>1 1 1</scale>
          </mesh>
        </geometry>
        <material>
          <ambient>0.2 0.2 0.2 1</ambient>
          <diffuse>0.2 0.2 0.2 1</diffuse>
        </material>
      </visual>
    </link>
    <joint name='front_left_wheel_joint' type='revolute'>
      <parent>front_left_steering_link</parent>
      <child>front_left_wheel_link</child>
      <axis>
        <xyz>0 1 0</xyz>
        <limit>
          <effort>200</effort>
          <velocity>100</velocity>
          <lower>-1e+16</lower>
          <upper>1e+16</upper>
        </limit>
        <dynamics>
          <damping>0.01</damping>
          <friction>0.01</friction>
          <spring_reference>0</spring_reference>
          <spring_stiffness>0</spring_stiffness>
        </dynamics>
      </axis>
    </joint>
    <link name='front_right_steering_link'>
      <pose>0.478 -0.275 0.1 0 -0 0</pose>
      <inertial>
        <mass>2</mass>
        <inertia>
          <ixx>0.01</ixx>
          <iyy>0.01</iyy>
          <izz>0.01</izz>
          <ixy>0</ixy>
          <ixz>0</ixz>
          <iyz>0</iyz>
        </inertia>
      </inertial>
      <collision name='front_right_steering_collision'>
        <pose>0 0 0.227 3.14159 3e-06 3e-06</pose>
        <geometry>
          <mesh>
            <uri>model://tadeocar_v1/meshes/suspension/suspension.dae</uri>
            <scale>1 1 1</scale>
          </mesh>
        </geometry>
      </collision>
      <visual name='front_right_steering_visual'>
        <pose>0 0 0.227 3.14159 3e-06 3e-06</pose>
        <geometry>
          <mesh>
            <uri>model://tadeocar_v1/meshes/suspension/suspension.dae</uri>
            <scale>1 1 1</scale>
          </mesh>
        </geometry>
        <material>
          <ambient>0.5 0.5 0.5 1</ambient>
          <diffuse>0.5 0.5 0.5 1</diffuse>
        </material>
      </visual>
    </link>
    <joint name='front_right_steering_joint' type='revolute'>
      <parent>base_link</parent>
      <child>front_right_steering_link</child>
      <axis>
        <xyz>0 0 1</xyz>
        <limit>
          <lower>-0.5</lower>
          <upper>0.5</upper>
          <effort>100</effort>
          <velocity>1</velocity>
        </limit>
        <dynamics>
          <damping>1</damping>
          <friction>1</friction>
          <spring_reference>0</spring_reference>
          <spring_stiffness>0</spring_stiffness>
        </dynamics>
      </axis>
    </joint>
    <link name='front_right_wheel_link'>
      <pose>0.528 -0.275 0.1 0 -0 0</pose>
      <inertial>
        <mass>3</mass>
        <inertia>
          <ixx>0.1</ixx>
          <iyy>0.1</iyy>
          <izz>0.1</izz>
          <ixy>0</ixy>
          <ixz>0</ixz>
          <iyz>0</iyz>
        </inertia>
      </inertial>
      <collision name='front_right_wheel_collision'>
        <pose>0 0 0 1.5708 -0 0</pose>
        <geometry>
          <mesh>
            <uri>model://tadeocar_v1/meshes/wheels/wheel.dae</uri>
            <scale>1 1 1</scale>
          </mesh>
        </geometry>
        <surface>
          <friction>
            <ode>
              <mu>1</mu>
              <mu2>1</mu2>
            </ode>
          </friction>
        </surface>
      </collision>
      <visual name='front_right_wheel_visual'>
        <pose>0 0 0 1.5708 -0 0</pose>
        <geometry>
          <mesh>
            <uri>model://tadeocar_v1/meshes/wheels/wheel.dae</uri>
            <scale>1 1 1</scale>
          </mesh>
        </geometry>
        <material>
          <ambient>0.2 0.2 0.2 1</ambient>
          <diffuse>0.2 0.2 0.2 1</diffuse>
        </material>
      </visual>
    </link>
    <joint name='front_right_wheel_joint' type='revolute'>
      <parent>front_right_steering_link</parent>
      <child>front_right_wheel_link</child>
      <axis>
        <xyz>0 1 0</xyz>
        <limit>
          <effort>200</effort>
          <velocity>100</velocity>
          <lower>-1e+16</lower>
          <upper>1e+16</upper>
        </limit>
        <dynamics>
          <damping>0.01</damping>
          <friction>0.01</friction>
          <spring_reference>0</spring_reference>
          <spring_stiffness>0</spring_stiffness>
        </dynamics>
      </axis>
    </joint>
    <link name='rear_left_steering_link'>
      <pose>-0.58 0.275 0.1 0 -0 0</pose>
      <inertial>
        <mass>2</mass>
        <inertia>
          <ixx>0.01</ixx>
          <iyy>0.01</iyy>
          <izz>0.01</izz>
          <ixy>0</ixy>
          <ixz>0</ixz>
          <iyz>0</iyz>
        </inertia>
      </inertial>
      <collision name='rear_left_steering_collision'>
        <pose>0 0 0.227 3.14159 3e-06 3.14159</pose>
        <geometry>
          <mesh>
            <uri>model://tadeocar_v1/meshes/suspension/suspension.dae</uri>
            <scale>1 1 1</scale>
          </mesh>
        </geometry>
      </collision>
      <visual name='rear_left_steering_visual'>
        <pose>0 0 0.227 3.14159 3e-06 3.14159</pose>
        <geometry>
          <mesh>
            <uri>model://tadeocar_v1/meshes/suspension/suspension.dae</uri>
            <scale>1 1 1</scale>
          </mesh>
        </geometry>
        <material>
          <ambient>0.5 0.5 0.5 1</ambient>
          <diffuse>0.5 0.5 0.5 1</diffuse>
        </material>
      </visual>
    </link>
    <joint name='rear_left_steering_joint' type='revolute'>
      <parent>base_link</parent>
      <child>rear_left_steering_link</child>
      <axis>
        <xyz>0 0 1</xyz>
        <limit>
          <lower>-0.5</lower>
          <upper>0.5</upper>
          <effort>100</effort>
          <velocity>1</velocity>
        </limit>
        <dynamics>
          <damping>1</damping>
          <friction>1</friction>
          <spring_reference>0</spring_reference>
          <spring_stiffness>0</spring_stiffness>
        </dynamics>
      </axis>
    </joint>
    <link name='rear_left_wheel_link'>
      <pose>-0.63 0.275 0.1 0 -0 0</pose>
      <inertial>
        <mass>3</mass>
        <inertia>
          <ixx>0.1</ixx>
          <iyy>0.1</iyy>
          <izz>0.1</izz>
          <ixy>0</ixy>
          <ixz>0</ixz>
          <iyz>0</iyz>
        </inertia>
      </inertial>
      <collision name='rear_left_wheel_collision'>
        <pose>0 0 0 1.5708 -0 0</pose>
        <geometry>
          <mesh>
            <uri>model://tadeocar_v1/meshes/wheels/wheel.dae</uri>
            <scale>1 1 1</scale>
          </mesh>
        </geometry>
        <surface>
          <friction>
            <ode>
              <mu>1</mu>
              <mu2>1</mu2>
            </ode>
          </friction>
        </surface>
      </collision>
      <visual name='rear_left_wheel_visual'>
        <pose>0 0 0 1.5708 -0 0</pose>
        <geometry>
          <mesh>
            <uri>model://tadeocar_v1/meshes/wheels/wheel.dae</uri>
            <scale>1 1 1</scale>
          </mesh>
        </geometry>
        <material>
          <ambient>0.2 0.2 0.2 1</ambient>
          <diffuse>0.2 0.2 0.2 1</diffuse>
        </material>
      </visual>
    </link>
    <joint name='rear_left_wheel_joint' type='revolute'>
      <parent>rear_left_steering_link</parent>
      <child>rear_left_wheel_link</child>
      <axis>
        <xyz>0 1 0</xyz>
        <limit>
          <effort>200</effort>
          <velocity>100</velocity>
          <lower>-1e+16</lower>
          <upper>1e+16</upper>
        </limit>
        <dynamics>
          <damping>0.01</damping>
          <friction>0.01</friction>
          <spring_reference>0</spring_reference>
          <spring_stiffness>0</spring_stiffness>
        </dynamics>
      </axis>
    </joint>
    <link name='rear_right_steering_link'>
      <pose>-0.58 -0.275 0.1 0 -0 0</pose>
      <inertial>
        <mass>2</mass>
        <inertia>
          <ixx>0.01</ixx>
          <iyy>0.01</iyy>
          <izz>0.01</izz>
          <ixy>0</ixy>
          <ixz>0</ixz>
          <iyz>0</iyz>
        </inertia>
      </inertial>
      <collision name='rear_right_steering_collision'>
        <pose>0 0 0.227 3.14159 3e-06 3.14159</pose>
        <geometry>
          <mesh>
            <uri>model://tadeocar_v1/meshes/suspension/suspension.dae</uri>
            <scale>1 1 1</scale>
          </mesh>
        </geometry>
      </collision>
      <visual name='rear_right_steering_visual'>
        <pose>0 0 0.227 3.14159 3e-06 3.14159</pose>
        <geometry>
          <mesh>
            <uri>model://tadeocar_v1/meshes/suspension/suspension.dae</uri>
            <scale>1 1 1</scale>
          </mesh>
        </geometry>
        <material>
          <ambient>0.5 0.5 0.5 1</ambient>
          <diffuse>0.5 0.5 0.5 1</diffuse>
        </material>
      </visual>
    </link>
    <joint name='rear_right_steering_joint' type='revolute'>
      <parent>base_link</parent>
      <child>rear_right_steering_link</child>
      <axis>
        <xyz>0 0 1</xyz>
        <limit>
          <lower>-0.5</lower>
          <upper>0.5</upper>
          <effort>100</effort>
          <velocity>1</velocity>
        </limit>
        <dynamics>
          <damping>1</damping>
          <friction>1</friction>
          <spring_reference>0</spring_reference>
          <spring_stiffness>0</spring_stiffness>
        </dynamics>
      </axis>
    </joint>
    <link name='rear_right_wheel_link'>
      <pose>-0.63 -0.275 0.1 0 -0 0</pose>
      <inertial>
        <mass>3</mass>
        <inertia>
          <ixx>0.1</ixx>
          <iyy>0.1</iyy>
          <izz>0.1</izz>
          <ixy>0</ixy>
          <ixz>0</ixz>
          <iyz>0</iyz>
        </inertia>
      </inertial>
      <collision name='rear_right_wheel_collision'>
        <pose>0 0 0 1.5708 -0 0</pose>
        <geometry>
          <mesh>
            <uri>model://tadeocar_v1/meshes/wheels/wheel.dae</uri>
            <scale>1 1 1</scale>
          </mesh>
        </geometry>
        <surface>
          <friction>
            <ode>
              <mu>1</mu>
              <mu2>1</mu2>
            </ode>
          </friction>
        </surface>
      </collision>
      <visual name='rear_right_wheel_visual'>
        <pose>0 0 0 1.5708 -0 0</pose>
        <geometry>
          <mesh>
            <uri>model://tadeocar_v1/meshes/wheels/wheel.dae</uri>
            <scale>1 1 1</scale>
          </mesh>
        </geometry>
        <material>
          <ambient>0.2 0.2 0.2 1</ambient>
          <diffuse>0.2 0.2 0.2 1</diffuse>
        </material>
      </visual>
    </link>
    <joint name='rear_right_wheel_joint' type='revolute'>
      <parent>rear_right_steering_link</parent>
      <child>rear_right_wheel_link</child>
      <axis>
        <xyz>0 1 0</xyz>
        <limit>
          <effort>200</effort>
          <velocity>100</velocity>
          <lower>-1e+16</lower>
          <upper>1e+16</upper>
        </limit>
        <dynamics>
          <damping>0.01</damping>
          <friction>0.01</friction>
          <spring_reference>0</spring_reference>
          <spring_stiffness>0</spring_stiffness>
        </dynamics>
      </axis>
    </joint>
    <link name='base_scan'>
      <pose>0 0 0.3 0 -0 0</pose>
      <inertial>
        <mass>0.125</mass>
        <inertia>
          <ixx>0.001</ixx>
          <iyy>0.001</iyy>
          <izz>0.001</izz>
          <ixy>0</ixy>
          <ixz>0</ixz>
          <iyz>0</iyz>
        </inertia>
      </inertial>
      <collision name='lidar_sensor_collision'>
        <geometry>
          <cylinder>
            <radius>0.035</radius>
            <length>0.03</length>
          </cylinder>
        </geometry>
      </collision>
      <visual name='lidar_sensor_visual'>
        <geometry>
          <cylinder>
            <radius>0.035</radius>
            <length>0.03</length>
          </cylinder>
        </geometry>
        <material>
          <ambient>0.1 0.1 0.1 1</ambient>
          <diffuse>0.1 0.1 0.1 1</diffuse>
        </material>
      </visual>
      <sensor name='hls_lfcd_lds' type='ray'>
        <pose>0 0 0 0 -0 0</pose>
        <always_on>1</always_on>
        <visualize>1</visualize>
        <update_rate>20</update_rate>
        <ray>
          <scan>
            <horizontal>
              <samples>360</samples>
              <resolution>2</resolution>
              <min_angle>0</min_angle>
              <max_angle>6.28</max_angle>
            </horizontal>
          </scan>
          <range>
            <min>0.12</min>
            <max>3.5</max>
            <resolution>0.02</resolution>
          </range>
        </ray>
        <plugin name='laserscan' filename='libgazebo_ros_ray_sensor.so'>
          <ros>
            <remapping>~/out:=scan</remapping>
          </ros>
          <qos>
            <topic name='scan'>
              <publisher>
                <reliability>best_effort</reliability>
              </publisher>
            </topic>
          </qos>
          <output_type>sensor_msgs/LaserScan</output_type>
          <frame_name>base_scan</frame_name>
        </plugin>
      </sensor>
    </link>
    <joint name='lidar_joint' type='fixed'>
      <parent>base_link</parent>
      <child>base_scan</child>
    </joint>
    <plugin name='gazebo_ros2_control' filename='libgazebo_ros2_control.so'>
      <parameters>/home/axioma/ros2/TadeoeCar-ws/install/tadeocar_control/share/tadeocar_control/config/ros2_controllers.yaml</parameters>
    </plugin>
  </model>
</sdf>
